Workbook

Sheet README
A1: L&M Gear Rental Redesign — Kit-Builder Starter Database
A2: Seed data for the AI kit-builder prototype (UI/UX case study — jaivalshah.com)
A4: WHAT'S IN THIS WORKBOOK
A5: Inventory — real Long & McQuade catalog items, rates, and links, from your own rental sheet.
A6: Kit Templates — the 4 named packages from your sheet (Standard PA, Panel/Conference, Recording/Hybrid
A7: Meeting, Presentation + Projector), rebuilt as formulas against Inventory so totals recalculate.
A8: Heuristic Rules — guest-count / event-type / venue rules for scenarios the 4 fixed packages don't cover
A9: (weddings, DJ sets, live bands) — the table an LLM would query for e.g. 'outdoor wedding, 100 guests'.
A11: HOW THE AI FEATURE WOULD USE THIS
A12: 1. User enters event type + guest count + venue (indoor/outdoor) on the kit-builder screen.
A13: 2. If it matches a named package (e.g. a panel discussion), return that Kit Template directly.
A14: 3. Otherwise, look up the nearest row in Heuristic Rules for target wattage / mic counts / fixtures,
... A50: number). Both are flagged yellow in Inventory.

Sheet Inventory
A1: Category | B1: Product | C1: Rental/Day | D1: Rental/Month | E1: Location | F1: Link | G1: Notes | H1: Image Source (reference)
A2: Speakers | B2: Yorkville Sound YXL12P 12 Inch 1000 Watt Powered Loudspeaker | C2: 11 | D2: 43 | E2: Vancouver (Broadway) | F2: https://www.long-mcquade.com/165008/Pro-Audio-Recording/PA-Speaker-Cabinets/Yorkville-Sound/YXL12P-12-Inch-1000-Watt-Powered-Loudspeaker.htm | G2: [Image: Manufacturer (Yorkville)] | H2: https://yorkville.com/loudspeakers/yxl/product/yxl12p
A3: Speakers | B3: Yorkville SoundEXM Mobile Tower Battery Powered PA System | C3: 25 | D3: 100 | F3: https://www.long-mcquade.com/347101/Pro-Audio-Recording/PA-Speaker-Cabinets/Yorkville-Sound/EXM-Mobile-Tower-Battery-Powered-PA-System.htm | G3: [Image: Manufacturer (Yorkville)] | H3: https://yorkville.com/loudspeakers/exm/product/exm-mobile-tower
A4: Speakers | B4: Yorkville Sound Tripod Boom Stand - Black | C4: 2 | D4: 7 | F4: https://www.long-mcquade.com/8769/Pro-Audio-Recording/Furniture-Stands/Yorkville-Sound/Tripod-Boom-Stand-Black.htm | G4: [Image: L&M product page (own photo)] | H4: https://www.long-mcquade.com/8769/Furniture-Stands/Stands/Yorkville-Sound/Tripod-Boom-Stand-Black.htm
A5: Visual | B5: Epson PowerLite 2140W WXGA 3LCD Projector | C5: 63 | D5: 250 | F5: https://www.long-mcquade.com/84242/Pro-Audio-Recording/Lighting/Epson/PowerLite-2140W-WXGA-3LCD-Projector.htm | G5: [Image: Manufacturer (Epson)] | H5: https://epson.com/For-Work/Projectors/Meeting-Room/PowerLite-2140W-WXGA-3LCD-Projector/p/V11H819020
A6: Visual | B6: 135in 10x6 projector screen | G6: Price/link not in original sheet — fill in. [Image: No matching real product found — this line item is too generic (no brand/model) to source an image for.] | H6: TBD
A7: Visual | B7: Grandview 80 Inch X-Press Pull-Up Projector Screen | C7: 15 | D7: 60 | F7: https://www.long-mcquade.com/65781/Pro-Audio-Recording/Lighting/Grandview/80-Inch-X-Press-Pull-Up-Projector-Screen.htm | G7: [Image: L&M product page (own photo)] | H7: https://www.long-mcquade.com/65781/Pro-Audio-Recording/Lighting/Grandview/80-Inch-X-Press-Pull-Up-Projector-Screen.htm
A8: Visual | B8: Grandview Cyber X-Press Series Pull-Up Projector Screen - 92" | C8: 20 | D8: 80 | F8: https://www.long-mcquade.com/65782/Pro-Audio-Recording/Lighting-Fog-Machines/Grandview/92-Inch-X-Press-Pull-Up-Projector-Screen.htm | G8: [Image: L&M product page (own photo)] | H8: https://www.long-mcquade.com/65782/Pro-Audio-Recording/Lighting-Fog-Machines/Grandview/92-Inch-X-Press-Pull-Up-Projector-Screen.htm
A9: Visual | B9: Zoom Q8N Handheld 4K video and audio Recorder | C9: 13 | D9: 50 | F9: https://www.long-mcquade.com/274011/Pro-Audio-Recording/Video/Zoom/Q8N-4K-Handheld-4K-Audio-and-Video-Recorder.htm | G9: [Image: Major retailer (B&H) — Zoom's own site lists the older Q8, not the Q8n-4K] | H9: https://www.bhphotovideo.com/c/product/1687971-REG/zoom_zq8n4k_q8n_4k_handy_video_recorder.html
A10: Microphones | B10: Shure SM58 Unidirectional/Cardioid Dynamic Microphone | C10: 5 | D10: 18 | F10: https://www.long-mcquade.com/1093/Pro-Audio-Recording/Microphones-Vocal-Processors/Shure/SM58-Unidirectional-Cardioid-Dynamic-Microphone.htm | G10: [Image: L&M product page (own photo)] | H10: https://www.long-mcquade.com/1093/Pro-Audio-Recording/Microphones-Vocal-Processors/Shure/SM58-Unidirectional-Cardioid-Dynamic-Microphone.htm
A11: Microphones | B11: Shure e835 Evolution Handheld Cardioid Microphone | F11: https://www.long-mcquade.com/1093/Pro-Audio-Recording/Microphones-Vocal-Processors/Shure/SM58-Unidirectional-Cardioid-Dynamic-Microphone.htm | G11: Link + price look copy/pasted from the SM58 row in your sheet — check and fill in the real e835 rate/link. [Image: Manufacturer (Sennheiser) — NAME CORRECTION: this is a Sennheiser e835, not a Shure product. Shure has no e835 model; fix the brand in your source sheet.] | H11: https://www.sennheiser.com/en-us/catalog/products/microphones/e-835/e-835-004513
A12: Microphones | B12: Shure CVB-B/O Omnidirectional Installed Boundary Microphone | F12: https://www.long-mcquade.com/189132/Pro-Audio-Recording/Microphones-Vocal-Processors/Shure/CVB-B-O-Omnidirectional-Installed-Boundary-Microphone-with-12ft-Cable-Black.htm | G12: Price not in original sheet — fill in. [Image: L&M product page (own photo)] | H12: https://www.long-mcquade.com/189132/Pro-Audio-Recording/Microphones-Vocal-Processors/Shure/CVB-B-O-Omnidirectional-Installed-Boundary-Microphone-with-12ft-Cable-Black.htm
A13: Microphones | B13: Apex Compact Boundary Microphone | C13: 4 | D13: 15 | G13: No link in original sheet — fill in. [Image: No confirmed real source found yet — search by exact Apex model number once you have it.] | H13: TBD
A14: Microphones | B14: Sennheiser EW 112-P G4-A Portable Lavalier Set | C14: 18 | D14: 70 | F14: https://www.long-mcquade.com/111871/Pro-Audio-Recording/Wireless-Systems/Sennheiser/EW-112P-G4-A-Portable-Lavalier-Set.htm | G14: [Image: Major retailer (B&H)] | H14: https://www.bhphotovideo.com/c/product/1385595-REG/sennheiser_ew_112p_g4_a_ew_112p_g4_camera.html
A15: Microphones | B15: Podium mic (model TBD) | G15: Referenced in Panel/Conference + Recording/Hybrid Meeting packages but not in your price list — add real model/rate. [Image: No real model chosen yet — add an image source once you pick one.] | H15: TBD
A16: Mixers & Extras | B16: Yorkville 8-Channel Passive Mixer | C16: 6 | D16: 23 | F16: https://www.long-mcquade.com/17950/Pro-Audio-Recording/Mixers/Yorkville-Sound/8-Channel-Passive-Mixer.htm | G16: [Image: Manufacturer (Yorkville) — model PGM8] | H16: https://www.yorkville.com/mixers/passive/product/pgm8/
A17: Mixers & Extras | B17: Yorkville 14-Channel Compact Desk Mixer | C17: 9 | D17: 35 | F17: https://www.long-mcquade.com/20283/Pro-Audio-Recording/Mixers/Yorkville-Sound/14-Channel-Compact-Desk-Mixer.htm | G17: [Image: Manufacturer (Yorkville) — model VGM14] | H17: https://www.yorkville.com/mixers/passive/product/vgm14/
A18: Mixers & Extras | B18: Yorkville 24 Channel x 4 XLR Returns - 100 foot | C18: 17 | D18: 68 | F18: https://www.long-mcquade.com/4377/Pro-Audio-Recording/Cables/Yorkville-Sound/24-Channel-x-4-XLR-Returns-100-foot.htm | G18: [Image: L&M product page (own photo)] | H18: https://www.long-mcquade.com/4377/Pro-Audio-Recording/Cables/Yorkville-Sound/24-Channel-x-4-XLR-Returns-100-foot.htm
A20: Location column: only row 2 is filled in as an example — for the real multi-location build, each item would repeat one row per branch that stocks it, with its own availability.

Sheet Kit Templates
A1: Package | B1: Item | C1: Qty | D1: Day Rate | E1: Line Day Cost | F1: Month Rate | G1: Line Month Cost
A2: Standard PA Package
A3: A classic 2-speaker PA for small bands, DJs, ceremonies or larger presentations. Good for small halls, community centres, gyms, etc.
A4: Standard PA Package | B4: Yorkville Sound YXL12P 12 Inch 1000 Watt Powered Loudspeaker | C4: 2 | D4: =Inventory!C2 -> 11 | E4: =IF(D4="",0,C4*D4) -> 22 | F4: =Inventory!D2 -> 43 | G4: =IF(F4="",0,C4*F4) -> 86
A5: Standard PA Package | B5: Yorkville 14-Channel Compact Desk Mixer | C5: 1 | D5: =Inventory!C17 -> 9 | E5: =IF(D5="",0,C5*D5) -> 9 | F5: =Inventory!D17 -> 35 | G5: =IF(F5="",0,C5*F5) -> 35
A6: Standard PA Package | B6: Shure SM58 Unidirectional/Cardioid Dynamic Microphone | C6: 2 | D6: =Inventory!C10 -> 5 | E6: =IF(D6="",0,C6*D6) -> 10 | F6: =Inventory!D10 -> 18 | G6: =IF(F6="",0,C6*F6) -> 36
A7: Standard PA Package | B7: Yorkville Sound Tripod Boom Stand - Black | C7: 2 | D7: =Inventory!C4 -> 2 | E7: =IF(D7="",0,C7*D7) -> 4 | F7: =Inventory!D4 -> 7 | G7: =IF(F7="",0,C7*F7) -> 14
B8: Computed Total (from Inventory rates above) | E8: =SUM(E4:E7) -> 45 | G8: =SUM(G4:G7) -> 171
B9: As-quoted in your original sheet (reference) | E9: 73 | G9: 285
A11: Panel/Conference Package
A12: Designed for panel discussions, town halls, board meetings and community forums where multiple people need mics — handhelds, table mics, podium, wireless lav.
A13: Panel/Conference Package | B13: Yorkville Sound YXL12P 12 Inch 1000 Watt Powered Loudspeaker | C13: 2 | D13: =Inventory!C2 -> 11 | E13: =IF(D13="",0,C13*D13) -> 22 | F13: =Inventory!D2 -> 43 | G13: =IF(F13="",0,C13*F13) -> 86
A14: Panel/Conference Package | B14: Yorkville 14-Channel Compact Desk Mixer | C14: 1 | D14: =Inventory!C17 -> 9 | E14: =IF(D14="",0,C14*D14) -> 9 | F14: =Inventory!D17 -> 35 | G14: =IF(F14="",0,C14*F14) -> 35
A15: Panel/Conference Package | B15: Shure SM58 Unidirectional/Cardioid Dynamic Microphone | C15: 3 | D15: =Inventory!C10 -> 5 | E15: =IF(D15="",0,C15*D15) -> 15 | F15: =Inventory!D10 -> 18 | G15: =IF(F15="",0,C15*F15) -> 54
A16: Panel/Conference Package | B16: Podium mic (model TBD) | C16: 1 | D16: =Inventory!C15 -> 0 | E16: =IF(D16="",0,C16*D16) -> 0 | F16: =Inventory!D15 -> 0 | G16: =IF(F16="",0,C16*F16) -> 0
A17: Panel/Conference Package | B17: Sennheiser EW 112-P G4-A Portable Lavalier Set | C17: 1 | D17: =Inventory!C14 -> 18 | E17: =IF(D17="",0,C17*D17) -> 18 | F17: =Inventory!D14 -> 70 | G17: =IF(F17="",0,C17*F17) -> 70
A18: Panel/Conference Package | B18: Yorkville Sound Tripod Boom Stand - Black | C18: 3 | D18: =Inventory!C4 -> 2 | E18: =IF(D18="",0,C18*D18) -> 6 | F18: =Inventory!D4 -> 7 | G18: =IF(F18="",0,C18*F18) -> 21
B19: Computed Total (from Inventory rates above) | E19: =SUM(E13:E18) -> 70 | G19: =SUM(G13:G18) -> 266
B20: As-quoted in your original sheet (reference) | E20: 105 | G20: 405
A21: Note: Total will be short vs. your $105/$405 until Podium mic has a real rate — see Inventory.
A23: Recording/Hybrid Meeting Package
A24: For events that need to be recorded or streamed (Zoom/Teams/YouTube) as well as heard clearly in the room. Good for panels, lectures and town halls.
A25: Recording/Hybrid Meeting Package | B25: Yorkville Sound YXL12P 12 Inch 1000 Watt Powered Loudspeaker | C25: 2 | D25: =Inventory!C2 -> 11 | E25: =IF(D25="",0,C25*D25) -> 22 | F25: =Inventory!D2 -> 43 | G25: =IF(F25="",0,C25*F25) -> 86
A26: Recording/Hybrid Meeting Package | B26: Yorkville 14-Channel Compact Desk Mixer | C26: 1 | D26: =Inventory!C17 -> 9 | E26: =IF(D26="",0,C26*D26) -> 9 | F26: =Inventory!D17 -> 35 | G26: =IF(F26="",0,C26*F26) -> 35
A27: Recording/Hybrid Meeting Package | B27: Shure SM58 Unidirectional/Cardioid Dynamic Microphone | C27: 1 | D27: =Inventory!C10 -> 5 | E27: =IF(D27="",0,C27*D27) -> 5 | F27: =Inventory!D10 -> 18 | G27: =IF(F27="",0,C27*F27) -> 18
A28: Recording/Hybrid Meeting Package | B28: Podium mic (model TBD) | C28: 1 | D28: =Inventory!C15 -> 0 | E28: =IF(D28="",0,C28*D28) -> 0 | F28: =Inventory!D15 -> 0 | G28: =IF(F28="",0,C28*F28) -> 0
A29: Recording/Hybrid Meeting Package | B29: Sennheiser EW 112-P G4-A Portable Lavalier Set | C29: 1 | D29: =Inventory!C14 -> 18 | E29: =IF(D29="",0,C29*D29) -> 18 | F29: =Inventory!D14 -> 70 | G29: =IF(F29="",0,C29*F29) -> 70
A30: Recording/Hybrid Meeting Package | B30: Yorkville Sound Tripod Boom Stand - Black | C30: 1 | D30: =Inventory!C4 -> 2 | E30: =IF(D30="",0,C30*D30) -> 2 | F30: =Inventory!D4 -> 7 | G30: =IF(F30="",0,C30*F30) -> 7
A31: Recording/Hybrid Meeting Package | B31: Zoom Q8N Handheld 4K video and audio Recorder | C31: 1 | D31: =Inventory!C9 -> 13 | E31: =IF(D31="",0,C31*D31) -> 13 | F31: =Inventory!D9 -> 50 | G31: =IF(F31="",0,C31*F31) -> 50
B32: Computed Total (from Inventory rates above) | E32: =SUM(E25:E31) -> 69 | G32: =SUM(G25:G31) -> 266
B33: As-quoted in your original sheet (reference) | E33: 0 | G33: 0
A34: Note: Your sheet showed $0.00 here (unfinished) — I added the Zoom Q8N recorder to the gear list since the Includes text names it and it's what makes this package different from Panel/Conference.
A36: Presentation + Projector Package
A37: Slides + sound. Ideal for keynotes, lectures, film nights or corporate presentations where you need both a big image and clear speech.
A38: Presentation + Projector Package | B38: Epson PowerLite 2140W WXGA 3LCD Projector | C38: 1 | D38: =Inventory!C5 -> 63 | E38: =IF(D38="",0,C38*D38) -> 63 | F38: =Inventory!D5 -> 250 | G38: =IF(F38="",0,C38*F38) -> 250
A39: Presentation + Projector Package | B39: Grandview Cyber X-Press Series Pull-Up Projector Screen - 92" | C39: 1 | D39: =Inventory!C8 -> 20 | E39: =IF(D39="",0,C39*D39) -> 20 | F39: =Inventory!D8 -> 80 | G39: =IF(F39="",0,C39*F39) -> 80
A40: Presentation + Projector Package | B40: Yorkville SoundEXM Mobile Tower Battery Powered PA System | C40: 1 | D40: =Inventory!C3 -> 25 | E40: =IF(D40="",0,C40*D40) -> 25 | F40: =Inventory!D3 -> 100 | G40: =IF(F40="",0,C40*F40) -> 100
A41: Presentation + Projector Package | B41: Shure SM58 Unidirectional/Cardioid Dynamic Microphone | C41: 1 | D41: =Inventory!C10 -> 5 | E41: =IF(D41="",0,C41*D41) -> 5 | F41: =Inventory!D10 -> 18 | G41: =IF(F41="",0,C41*F41) -> 18
A42: Presentation + Projector Package | B42: Yorkville Sound Tripod Boom Stand - Black | C42: 1 | D42: =Inventory!C4 -> 2 | E42: =IF(D42="",0,C42*D42) -> 2 | F42: =Inventory!D4 -> 7 | G42: =IF(F42="",0,C42*F42) -> 7
B43: Computed Total (from Inventory rates above) | E43: =SUM(E38:E42) -> 115 | G43: =SUM(G38:G42) -> 455
...

Sheet Heuristic Rules
A1: Event Type | B1: Guest Count | C1: Venue | D1: Watts/Guest (target) | E1: Speaker Count | F1: Sub Count | G1: Wireless Mics | H1: Wired Mics | I1: Mixer Ch. (min) | J1: Source / Notes
A2: Wedding ceremony | B2: < 100 | C2: Outdoor | D2: 10–14 | E2: 2 | F2: 0–1 | G2: 2 | H2: 0 | I2: 4 | J2: Outdoor multiplier roughly doubles indoor wattage/guest rule of thumb (no room reinforcement, inverse-square loss).
A3: Wedding reception | B3: 100–200 | C3: Indoor | D3: 7–8 | E3: 2 | F3: 1 | G3: 2 | H3: 3 | I3: 8 | J3: Wired count assumes live tabla/keyboard/singer setup, matching your own gig rig.
A4: Wedding reception | B4: 300–400 | C4: Indoor | D4: 6–8 | E4: 2 | F4: 2 | G4: 2 | H4: 3 | I4: 8 | J4: Cross-checked against your Aria Banquet Hall quote Q-2026-19 (2x PS15 tops + 2x 15" subs, 300–400 guests).
A5: Corporate speech / panel | B5: Any | C5: Indoor | D5: 3–5 | E5: 2 | F5: 0 | G5: 3–4 | H5: 0 | I5: 6 | J5: Speech-only content needs far less power per guest than music — clarity over output.
A6: DJ set / club night | B6: 100–300 | C6: Indoor | D6: 8–12 | E6: 2–4 | F6: 2 | G6: 1 | H6: 0 | I6: 4 | J6: Higher watts/guest for dance-floor content; add speakers past ~5,000 sq ft or delay stacks beyond 80–100 ft throw.
A8: Lighting fixture-count rules not yet drafted — decide fixture-count-by-guest-tier vs. uplighting-by-room-perimeter before adding a Lighting column here.
